[2019-12-10 15:27:50,844] connectionpool.py->urlopen line:665 [WARNING]Retrying (Retry(total=2, connect=3, read=None, redirect=None, status=None)) after connection broken by 'ProtocolError('Connection aborted.', RemoteDisconnected('Remote end closed connection without response',))': /version
[2019-12-10 15:27:51,855] connectionpool.py->urlopen line:665 [WARNING]Retrying (Retry(total=1, connect=3, read=None, redirect=None, status=None)) after connection broken by 'ProtocolError('Connection aborted.', RemoteDisconnected('Remote end closed connection without response',))': /version
[2019-12-10 15:27:53,863] connectionpool.py->urlopen line:665 [WARNING]Retrying (Retry(total=0, connect=3, read=None, redirect=None, status=None)) after connection broken by 'ProtocolError('Connection aborted.', RemoteDisconnected('Remote end closed connection without response',))': /version
[2019-12-10 15:27:54,548] connectionpool.py->urlopen line:665 [WARNING]Retrying (Retry(total=2, connect=3, read=None, redirect=None, status=None)) after connection broken by 'ProtocolError('Connection aborted.', RemoteDisconnected('Remote end closed connection without response',))': /version
[2019-12-10 15:27:55,560] connectionpool.py->urlopen line:665 [WARNING]Retrying (Retry(total=1, connect=3, read=None, redirect=None, status=None)) after connection broken by 'ProtocolError('Connection aborted.', RemoteDisconnected('Remote end closed connection without response',))': /version
[2019-12-10 15:27:57,574] connectionpool.py->urlopen line:665 [WARNING]Retrying (Retry(total=0, connect=3, read=None, redirect=None, status=None)) after connection broken by 'ProtocolError('Connection aborted.', RemoteDisconnected('Remote end closed connection without response',))': /version
[2019-12-10 15:27:57,685] connectionpool.py->urlopen line:665 [WARNING]Retrying (Retry(total=2, connect=3, read=None, redirect=None, status=None)) after connection broken by 'ProtocolError('Connection aborted.', RemoteDisconnected('Remote end closed connection without response',))': /version
[2019-12-10 15:27:58,697] connectionpool.py->urlopen line:665 [WARNING]Retrying (Retry(total=1, connect=3, read=None, redirect=None, status=None)) after connection broken by 'ProtocolError('Connection aborted.', RemoteDisconnected('Remote end closed connection without response',))': /version
[2019-12-10 15:27:58,713] conftest.py->login_logout line:227 [INFO]为避免正在运行先停止
[2019-12-10 15:27:58,791] conftest.py->login_logout line:231 [INFO]第一种方法，启动App（包名）
[2019-12-10 15:28:12,400] conftest.py->login_logout line:249 [INFO]设置xpath全局等待10s
[2019-12-10 15:28:12,400] conftest.py->login_logout line:263 [INFO]选择编程猫账号登录
[2019-12-10 15:28:12,411] api.py->__retry_internal line:40 [WARNING]uiautomator2.GatewayError(gateway error, time used 0.0s), retrying in 3.0 seconds...
[D 191210 15:28:15 __init__:639] force reset uiautomator
[D 191210 15:28:15 __init__:655] uiautomator(1.0) is starting ...
[D 191210 15:28:16 __init__:655] uiautomator(1.0) is starting ...
[I 191210 15:28:16 __init__:643] uiautomator back to normal
[2019-12-10 15:28:18,057] conftest.py->login_logout line:267 [INFO]点击账号，并切换成FastInputIME输入法输入username183
[2019-12-10 15:28:20,697] conftest.py->login_logout line:273 [INFO]点击密码，输入password183
[2019-12-10 15:28:31,805] conftest.py->login_logout line:278 [INFO]切换回正常输入法并点击登录按钮
[2019-12-10 15:28:41,809] conftest.py->login_logout line:298 [INFO]校验是否成功登录并进入首页
[2019-12-10 15:28:44,965] conftest.py->myteardown line:307 [INFO]获取设备udid
[2019-12-10 15:28:47,305] conftest.py->myteardown line:321 [INFO]为避免正在运行先停止
[2019-12-10 15:28:47,421] conftest.py->myteardown line:325 [INFO]第一种方法，启动App（包名）
[2019-12-10 15:29:01,107] conftest.py->myteardown line:336 [INFO]点击我的
[2019-12-10 15:29:02,737] conftest.py->myteardown line:341 [INFO]点击设置按钮
[2019-12-10 15:29:05,236] conftest.py->myteardown line:345 [INFO]从下滑到上（两次）
[2019-12-10 15:29:06,159] conftest.py->myteardown line:353 [INFO]点击退出登录
